<robot xmlns:xacro="http://ros.org/wiki/xacro"> 
 	<xacro:macro name="link_led" params="name parent *origin">
		<joint name="${name}_joint" type="continuous">
			<xacro:insert_block name="origin" />
			<parent link="${parent}"/>
			<child link="${name}_led"/>
		</joint>

		<link name="${name}_led">
			<inertial>
				<mass value="0.001" />
				<origin xyz="0 0 0" rpy="0 0 0" />
				<inertia ixx="0.0001" ixy="0" ixz="0" iyy="0.0001" iyz="0" izz="0.0001" />
			</inertial>
			<visual>
				<origin xyz="0 0 0" rpy="0 0 0" />
				<geometry>
					<sphere radius="0.02"/>
				</geometry>
			</visual>
			<collision>
				<origin xyz="0 0 0" rpy="0 0 0" />
				<geometry>
					<sphere radius="0.02"/>
				</geometry>
			</collision>
		</link>
	</xacro:macro>
</robot>
  

<!-- 
      <joint name="wheel_right_joint" type="continuous">
        <parent link="${X_ROBOT_NAMESPACE}/base_link"/>
        <child link="${X_ROBOT_NAMESPACE}/wheel_right_link"/>
        <origin xyz="0.00 -0.115 0.0250" rpy="-1.57079632679 0 0"/>
        <axis xyz="0 0 1"/>
      </joint>
      <link name="${X_ROBOT_NAMESPACE}/wheel_right_link">
        <visual>
          <geometry>
            <mesh filename="package://robot_descriptions/UGV/meshes/wheel.dae"/>
          </geometry>
          <origin xyz="0 0 0" rpy="0 0 0"/>
        </visual>
        <collision>
          <geometry>
            <cylinder length="0.0206" radius="0.0350"/>
          </geometry>
          <origin rpy="0 0 0" xyz="0 0 0"/>
        </collision>
        <inertial>
          <mass value="0.01" />
          <origin xyz="0 0 0" />        
          <inertia ixx="0.001" ixy="0.0" ixz="0.0" iyy="0.001" iyz="0.0" izz="0.001" />
        </inertial>
      </link>
 -->